<?xml version="1.0" encoding="UTF-8"?>
<robot generator="Robot 5.0 (Python 3.10.4 on win32)" generated="20220405 12:41:45.965" rpa="true" schemaversion="3">
<suite id="s1" name="Tasks" source="C:\git\SWE_Finanzen\robot_tests\tasks.robot">
<test id="s1-t1" name="Insert the sales data for the week and export it as a PDF" line="11">
<kw name="Open the intranet website">
<kw name="Start Virtual Display">
<arg>1920 1080</arg>
<msg timestamp="20220405 12:41:46.619" level="FAIL">No keyword with name 'Start Virtual Display' found.</msg>
<status status="FAIL" starttime="20220405 12:41:46.619" endtime="20220405 12:41:46.620"/>
</kw>
<kw name="Open Browser">
<arg>${LOGIN URL}</arg>
<status status="NOT RUN" starttime="20220405 12:41:46.627" endtime="20220405 12:41:46.627"/>
</kw>
<kw name="Set Windwos Size">
<arg>1820 1080</arg>
<status status="NOT RUN" starttime="20220405 12:41:46.632" endtime="20220405 12:41:46.632"/>
</kw>
<status status="FAIL" starttime="20220405 12:41:46.612" endtime="20220405 12:41:46.632"/>
</kw>
<status status="FAIL" starttime="20220405 12:41:46.608" endtime="20220405 12:41:46.640">No keyword with name 'Start Virtual Display' found.</status>
</test>
<doc>Template robot main suite.</doc>
<status status="FAIL" starttime="20220405 12:41:45.969" endtime="20220405 12:41:46.648"/>
</suite>
<statistics>
<total>
<stat pass="0" fail="1" skip="0">All Tasks</stat>
</total>
<tag>
</tag>
<suite>
<stat pass="0" fail="1" skip="0" id="s1" name="Tasks">Tasks</stat>
</suite>
</statistics>
<errors>
<msg timestamp="20220405 12:41:46.581" level="ERROR">Error in file 'C:\git\SWE_Finanzen\robot_tests\tasks.robot' on line 3: Initializing library 'SeleniumLibrary' with arguments [ XvfbRobot ] failed: ValueError: Invalid time string 'XvfbRobot'.
Traceback (most recent call last):
  File "C:\Users\otto\AppData\Local\Programs\Python\Python310\lib\site-packages\SeleniumLibrary\__init__.py", line 455, in __init__
    self.timeout = _convert_timeout(timeout)
  File "C:\Users\otto\AppData\Local\Programs\Python\Python310\lib\site-packages\SeleniumLibrary\utils\types.py", line 35, in _convert_timeout
    return timestr_to_secs(timeout)
  File "C:\Users\otto\AppData\Local\Programs\Python\Python310\lib\site-packages\robot\utils\robottime.py", line 52, in timestr_to_secs
    raise ValueError("Invalid time string '%s'." % timestr)
ValueError: Invalid time string 'XvfbRobot'.</msg>
</errors>
</robot>
